Workbook

Sheet Indicators_2022
A1: Column1 | B1: Time | C1: Time Code | D1: Country Name | E1: Country Code | F1: Population, total [SP.POP.TOTL] | G1: Population growth (annual %) [SP.POP.GROW] | H1: Surface area (sq. km) [AG.SRF.TOTL.K2] | I1: Poverty headcount ratio at national poverty lines (% of population) [SI.POV.NAHC] | J1: GNI, Atlas method (current US$) [NY.GNP.ATLS.CD] | K1: GNI per capita, Atlas method (current US$) [NY.GNP.PCAP.CD] | L1: GNI, PPP (current international $) [NY.GNP.MKTP.PP.CD] | M1: GNI per capita, PPP (current international $) [NY.GNP.PCAP.PP.CD] | N1: Income share held by lowest 20% [SI.DST.FRST.20] | O1: Life expectancy at birth, total (years) [SP.DYN.LE00.IN] | P1: Fertility rate, total (births per woman) [SP.DYN.TFRT.IN] | Q1: Adolescent fertility rate (births per 1,000 women ages 15-19) [SP.ADO.TFRT] | R1: Contraceptive prevalence, any method (% of married women ages 15-49) [SP.DYN.CONU.ZS] | S1: Births attended by skilled health staff (% of total) [SH.STA.BRTC.ZS] | T1: Mortality rate, under-5 (per 1,000 live births) [SH.DYN.MORT] | U1: Prevalence of underweight, weight for age (% of children under 5) [SH.STA.MALN.ZS] | V1: Immunization, measles (% of children ages 12-23 months) [SH.IMM.MEAS] | W1: Primary completion rate, total (% of relevant age group) [SE.PRM.CMPT.ZS] | X1: School enrollment, secondary (% gross) [SE.SEC.ENRR] | Y1: School enrollment, primary and secondary (gross), gender parity index (GPI) [SE.ENR.PRSC.FM.ZS] | Z1: Prevalence of HIV, total (% of population ages 15-49) [SH.DYN.AIDS.ZS] | AA1: Forest area (sq. km) [AG.LND.FRST.K2] | AB1: Water productivity, total (constant 2015 US$ GDP per cubic meter of total freshwater withdrawal) [ER.GDP.FWTL.M3.KD] | AC1: Energy use (kg of oil equivalent per capita) [EG.USE.PCAP.KG.OE] | AD1: Electric power consumption (kWh per capita) [EG.USE.ELEC.KH.PC] | AE1: GDP (current US$) [NY.GDP.MKTP.CD] | AF1: GDP growth (annual %) [NY.GDP.MKTP.KD.ZG] | AG1: Inflation, GDP deflator (annual %) [NY.GDP.DEFL.KD.ZG] | AH1: Agriculture, forestry, and fishing, value added (% of GDP) [NV.AGR.TOTL.ZS] | AI1: Industry (including construction), value added (% of GDP) [NV.IND.TOTL.ZS] | AJ1: Exports of goods and services (% of GDP) [NE.EXP.GNFS.ZS] | AK1: Imports of goods and services (% of GDP) [NE.IMP.GNFS.ZS] | AL1: Gross capital formation (% of GDP) [NE.GDI.TOTL.ZS] | AM1: Revenue, excluding grants (% of GDP) [GC.REV.XGRT.GD.ZS] | AN1: Market capitalization of listed domestic companies (% of GDP) [CM.MKT.LCAP.GD.ZS] | AO1: Military expenditure (% of GDP) [MS.MIL.XPND.GD.ZS] | AP1: Mobile cellular subscriptions (per 100 people) [IT.CEL.SETS.P2] | AQ1: High-technology exports (% of manufactured exports) [TX.VAL.TECH.MF.ZS] | AR1: Merchandise trade (% of GDP) [TG.VAL.TOTL.GD.ZS] | AS1: Net barter terms of trade index (2015 = 100) [TT.PRI.MRCH.XD.WD] | AT1: External debt stocks, total (DOD, current US$) [DT.DOD.DECT.CD] | AU1: Total debt service (% of GNI) [DT.TDS.DECT.GN.ZS] | AV1: Net migration [SM.POP.NETM] | AW1: Personal remittances, paid (current US$) [BM.TRF.PWKR.CD.DT] | AX1: Foreign direct investment, net inflows (BoP, current US$) [BX.KLT.DINV.CD.WD] | AY1: Net ODA received per capita (current US$) [DT.ODA.ODAT.PC.ZS] | AZ1: GDP per capita (current US$) [NY.GDP.PCAP.CD] | BA1: Foreign direct investment, net (BoP, current US$) [BN.KLT.DINV.CD] | BB1: Inflation, consumer prices (annual %) [FP.CPI.TOTL.ZG]
A2: 0 | B2: 2022 | C2: YR2022 | D2: Afghanistan | E2: AFG | F2: 40578842 | G2: 1.4357044 | H2: 652860 | J2: 1.4887595e+10 | K2: 370 | L2: 8.6404554e+10 | M2: 2130 | O2: 65.617 | P2: 4.932 | Q2: 65.339 | T2: 57.4 | U2: 18.4 | V2: 56 | Z2: 0.1 | AA2: 12084.4 | AB2: 0.75560762 | AE2: 1.4497244e+10 | AF2: -6.240172 | AG2: 9.4062393 | AH2: 33.701432 | AI2: 16.050368 | AJ2: 18.380042 | AK2: 54.505427 | AL2: 16.7 | AP2: 56.2655 | AR2: 32.068164 | AS2: 96.1 | AT2: 3.3932472e+09 | AU2: 0.18280878 | AV2: -647402 | AX2: 0 | AY2: 96.478038 | AZ2: 357.26115 | BB2: 13.712102
A3: 1 | B3: 2022 | C3: YR2022 | D3: Albania | E3: ALB | F3: 2451636 | G3: -1.5431567 | H3: 28750 | I3: 19.7 | J3: 1.8934768e+10 | K3: 7720 | L3: 5.3075778e+10 | M3: 21650 | O3: 78.769 | P3: 1.355 | Q3: 12.827 | T3: 9.4 | V3: 86 | W3: 101.17628 | X3: 97.322471 | Z3: 0.1 | AA3: 7889 | AB3: 18.049366 | AC3: 884.57222 | AD3: 2840.9601 | AE3: 1.9017247e+10 | AF3: 4.8268006 | AG3: 9.8616099 | AH3: 16.984475 | AI3: 23.025052 | AJ3: 37.197076 | AK3: 47.500968 | AL3: 26.802365 | AM3: 24.731661 | AO3: 1.2087886 | AP3: 98.395 | AQ3: 0.059640998 | AR3: 66.823552 | AS3: 115.8 | AT3: 1.0420148e+10 | AU3: 3.77623 | AV3: -16426 | AW3: 1.4948965e+08 | AX3: 1.4413819e+09 | AY3: 129.20652 | AZ3: 7756.9619 | BA3: -1.2498485e+09 | BB3: 6.7252027
A4: 2 | B4: 2022 | C4: YR2022 | D4: Algeria | E4: DZA | F4: 45477389 | G4: 1.5875821 | H4: 2381740 | J4: 2.0143949e+11 | K4: 4430 | L4: 7.0339254e+11 | M4: 15470 | O4: 76.129 | P4: 2.817 | Q4: 8.977 | T4: 22.3 | V4: 79 | W4: 93.929104 | X4: 104.55027 | Z4: 0.1 | AA4: 19680 | AB4: 20.080693 | AC4: 1499.51 | AD4: 1756.5872 | AE4: 2.2558164e+11 | AF4: 3.6 | AG4: 22.920306 | AH4: 10.647064 | AI4: 43.052131 | AJ4: 30.791556 | AK4: 20.398533 | AL4: 35.097954 | AO4: 4.0574881 | AP4: 107.787 | AR4: 46.362815 | AS4: 150.8 | AT4: 7.1292587e+09 | AU4: 0.13590795 | AV4: -14684 | AW4: 77927357 | AX4: 2.4179603e+08 | AY4: 4.7574499 | AZ4: 4960.3033 | BA4: -1.5720979e+08 | BB4: 9.2655155
A5: 3 | B5: 2022 | C5: YR2022 | D5: American Samoa | E5: ASM | F5: 48342 | G5: -1.8100877 | H5: 200 | O5: 72.752 | P5: 2.305 | Q5: 34.104 | AA5: 170.7 | AE5: 871000000 | AF5: 1.7350158 | AG5: 14.152765 | AJ5: 46.95752 | AK5: 77.726751 | AR5: 117.68083 | AS5: 181.8 | AV5: -1305 | AZ5: 18017.459
A6: 4 | B6: 2022 | C6: YR2022 | D6: Andorra | E6: AND | F6: 79705 | G6: 1.6967681 | H6: 470 | J6: 3.7936073e+09 | K6: 47600 | L6: 5.6922481e+09 | M6: 71420 | O6: 84.016 | P6: 1.071 | Q6: 3.527 | T6: 2.7 | V6: 98 | X6: 98.509872 | AA6: 160 | AE6: 3.3806117e+09 | AF6: 9.5646123 | AG6: 4.2366523 | AH6: 0.48749186 | AI6: 11.145341 | AM6: 29.381625 | AP6: 142.426 | AQ6: 13.307661 | AR6: 66.556002 | AS6: 92 | AV6: 1102 | AW6: 1.2388326e+08 | AX6: 5.9398142e+08 | AZ6: 42414.048 | BA6: -4.5060358e+08
A7: 5 | B7: 2022 | C7: YR2022 | D7: Angola | E7: AGO | F7: 35635029 | G7: 3.1430261 | H7: 1246700 | J7: 8.3435815e+10 | K7: 2340 | L7: 3.2081202e+11 | M7: 9000 | O7: 64.246 | P7: 5.209 | Q7: 141.978 | T7: 66.4 | V7: 50 | Z7: 1.6 | AA7: 654972.51 | AB7: 144.46414 | AC7: 423.12252 | AD7: 392.50705 | AE7: 1.3121221e+11 | AF7: 4.2160026 | AG7: 18.121772 | AH7: 18.989093 | AI7: 34.933359 | AJ7: 35.196053 | AK7: 20.05872 | AL7: 14.176986 | AM7: 26.016294 | AO7: 1.4101637 | AP7: 66.6008 | AQ7: 22.063504 | AR7: 52.646016 | AS7: 167.3 | AT7: 6.0445748e+10 | AU7: 12.402875 | AV7: -995 | AW7: 5.1766819e+08 | AX7: -6.5986527e+09 | AY7: 2.6920665 | AZ7: 3682.1132 | BA7: 6.639719e+09 | BB7: 21.35529
A8: 6 | B8: 2022 | C8: YR2022 | D8: Antigua and Barbuda | E8: ATG | F8: 92840 | G8: 0.53027032 | H8: 440 | J8: 1.7475498e+09 | K8: 18820 | L8: 2.6410557e+09 | M8: 28450 | O8: 77.483 | P8: 1.58 | Q8: 33.469 | T8: 9.6 | V8: 99 | W8: 123.35474 | X8: 107.79991 | Z8: 1.1 | AA8: 79.911 | AB8: 368.34 | AE8: 1.8665667e+09 | AF8: 9.1078062 | AG8: 6.7802747 | AH8: 1.9556603 | AI8: 19.658196 | AJ8: 54.723765 | AK8: 62.979763 | AP8: 200.541 | AQ8: 0 | AR8: 45.109559 | AS8: 80.1 | AV8: 0 | AW8: 55995755 | AX8: 3.1327009e+08 | AZ8: 20105.199 | BA8: -3.0382857e+08 | BB8: 7.5310783
A9: 7 | B9: 2022 | C9: YR2022 | D9: Argentina | E9: ARG | F9: 45407904 | G9: 0.21080873 | H9: 2780400 | I9: 39.2 | J9: 5.3979698e+11 | K9: 11890 | L9: 1.3286385e+12 | M9: 29260 | N9: 5.4 | O9: 75.806 | P9: 1.482 | Q9: 25.767 | T9: 9.8 | V9: 85 | W9: 100.31015 | X9: 114.14812 | Z9: 0.4 | AA9: 283550 | AB9: 15.995562 | AC9: 1808.7602 | AD9: 2833.1191 | AE9: 6.3399376e+11 | AF9: 6.0207454 | AG9: 68.993827 | AH9: 6.5415694 | AI9: 24.111864 | AJ9: 16.281668 | AK9: 15.298512 | AL9: 17.385586 | AM9: 17.893195 | AN9: 8.351475 | AO9: 0.68458641 | AP9: 131.484 | AQ9: 4.7515752 | AR9: 26.884019 | AS9: 114.2 | AT9: 248976650822 | AU9: 5.4479512 | AV9: 5589 | AW9: 5.8477318e+08 | AX9: 1.5206087e+10 | AY9: 8.4863981 | AZ9: 13962.189 | BA9: -1.3116251e+10 | BB9: 72.430758
A10: 8 | B10: 2022 | C10: YR2022 | D10: Armenia | E10: ARM | F10: 2969200 | G10: 0.23265626 | H10: 29740 | I10: 24.8 | J10: 1.6893971e+10 | K10: 5690 | L10: 5.5469245e+10 | M10: 18680 | N10: 9.2 | O10: 74.765854 | P10: 1.7 | Q10: 13.487 | T10: 10.5 | V10: 95 | W10: 93.824828 | X10: 91.710661 | Z10: 0.3 | AA10: 3280.5 | AB10: 4.6306808 | AC10: 1347.5906 | AD10: 2403.6778 | AE10: 1.9513507e+10 | AF10: 12.6 | AG10: 7.9858785 | AH10: 10.146704 | AI10: 25.437097 | AJ10: 51.57092 | AK10: 52.307709 | AL10: 22.255132 | AM10: 23.456418 | AN10: 1.2948467 | AO10: 4.081746 | AP10: 130.54 | AQ10: 21.847528 | AR10: 72.406259 | AS10: 98.6 | AT10: 1.5931153e+10 | AU10: 10.463451 | AV10: 38001 | AW10: 6.6633964e+08 | AX10: 9.7565891e+08 | AY10: 101.4859 | AZ10: 6571.9745 | BA10: -9.2591397e+08 | BB10: 8.6409111
A11: 9 | B11: 2022 | C11: YR2022 | D11: Aruba | E11: ABW | F11: 107310 | G11: -0.36277422 | H11: 180 | J11: 3.2362969e+09 | K11: 30160 | L11: 4.3130739e+09 | M11: 40190 | O11: 76.226 | P11: 1.615 | Q11: 18.768 | W11: 93.832939 | X11: 131.80217 | AA11: 4.2 | AE11: 3.3240344e+09 | AF11: 10.636431 | AG11: 4.2890599 | AH11: 0.034214432 | AI11: 9.7359174 | AJ11: 80.806881 | AK11: 79.827665 | AL11: 19.808067 | AP11: 130.648 | AQ11: 7.1251465 | AR11: 47.743188 | AS11: 72.9 | AV11: 152 | AW11: 1.1036104e+08 | AX11: 2.4815028e+08 | AZ11: 30975.999 | BA11: -1.2469428e+08
A12: 10 | B12: 2022 | C12: YR2022 | D12: Australia | E12: AUS | F12: 26018721 | G12: 1.2893113 | H12: 7741220 | J12: 1.5817646e+12 | K12: 60790 | L12: 1.6511382e+12 | M12: 63460 | O12: 83.2 | P12: 1.63 | Q12: 6.747 | T12: 3.7 | V12: 96 | X12: 133.27727 | Z12: 0.1 | AA12: 1340051 | AB12: 137.03594 | AC12: 4942.1637 | AD12: 9923.4317 | AE12: 1.6956275e+12 | AF12: 4.2530456 | AG12: 7.1995443 | AH12: 2.672427 | AI12: 27.401962 | AJ12: 25.46153 | AK12: 20.233112 | AL12: 23.699796 | AM12: 26.131348 | AN12: 99.029527 | AO12: 1.8832971 | AP12: 109.469 | AQ12: 25.83187 | AR12: 42.572557 | AS12: 181 | AV12: 140972 | AW12: 6.5305289e+09 | AX12: 6.870942e+10 | AZ12: 65169.519 | BA12: 5.8640231e+10 | BB12: 6.5940967
A13: 11 | B13: 2022 | C13: YR2022 | D13: Austria | E13: AUT | F13: 9041851 | G13: 0.9562878 | H13: 83879 | J13: 5.0917613e+11 | K13: 56310 | L13: 6.4245136e+11 | M13: 71050 | N13: 7.8 | O13: 81.295122 | P13: 1.41 | Q13: 4.205 | T13: 3.2 | V13: 95 | W13: 97.159172 | X13: 101.458 | AA13: 38954.5 | AB13: 136.29705 | AC13: 3486.7294 | AD13: 8256.6059 | AE13: 4.732213e+11 | AF13: 5.3309638 | AG13: 5.0234316 | AH13: 1.346496 | AI13: 25.844468 | AJ13: 61.427312 | AK13: 62.152267 | AL13: 29.236794 | AM13: 44.264983 | AN13: 26.002211 | AO13: 0.76670601 | AP13: 121.166 | AQ13: 14.91417 | AR13: 94.131012 | AS13: 94 | AV13: 157365 | AW13: 6.9496747e+09 | AX13: 1.4301504e+10 | AZ13: 52336.773 | BA13: 1.123624e+08 | BB13: 8.5468699
A14: 12 | B14: 2022 | C14: YR2022 | D14: Azerbaijan | E14: AZE | F14: 10141756 | G14: 0.039507866 | H14: 86600 | J14: 5.7455095e+10 | K14: 5670 | L14: 2.1337998e+11 | M14: 21040 | O14: 74.125 | P14: 1.67 | Q14: 35.293 | T14: 19.4 | V14: 71 | W14: 99.703281 | X14: 90.953036 | Z14: 0.1 | AA14: 11548.256 | AB14: 4.3593788 | AC14: 1714.0373 | AD14: 2365.8625 | AE14: 7.8807471e+10 | AF14: 4.7146803 | AG14: 37.270721 | AH14: 4.6122083 | AI14: 56.146737 | AJ14: 59.986848 | AK14: 26.995425 | AL14: 12.003714 | AM14: 38.448421 | AN14: 1.8627422 | AO14: 3.7953703 | AP14: 107.506 | AQ14: 3.9129442 | AR14: 66.855337 | AS14: 173.3 | AT14: 1.545749e+10 | AU14: 2.1831177 | AV14: 9086 | AW14: 811938000 | AX14: -4474481000 | AY14: 4.7819302 | AZ14: 7770.5942 | BA14: 4646691000 | BB14: 13.852259
A15: 13 | B15: 2022 | C15: YR2022 | D15: Bahamas, The | E15: BHS | F15: 397538 | G15: 0.29348399 | H15: 13880 | J15: 1.3432451e+10 | K15: 33790 | L15: 1.3834311e+10 | M15: 34800 | O15: 74.491 | P15: 1.379 | Q15: 24.679 | T15: 12.9 | V15: 80 | Z15: 1.2 | AA15: 5098.6 | AE15: 13896800000 | AF15: 10.877901 | AG15: 4.1241697 | AH15: 0.41448391 | AI15: 9.5043463 | AJ15: 37.158914 | AK15: 38.824046 | AL15: 23.815555 | AM15: 18.748902 | AP15: 101.624 | AQ15: 0 | AR15: 31.431697 | AS15: 98.9 | AV15: 1001 | AW15: 2.1650792e+08 | AX15: 5.3091395e+08 | AZ15: 34957.161 | BA15: -3.1643019e+08 | BB15: 5.6054063
A16: 14 | B16: 2022 | C16: YR2022 | D16: Bahrain | E16: BHR | F16: 1524693 | G16: 1.3422196 | H16: 790 | J16: 4.3142062e+10 | K16: 28300 | L16: 9.0066506e+10 | M16: 59070 | O16: 80.992 | P16: 1.839 | Q16: 8.122 | T16: 8.4 | V16: 99 | W16: 101.04302 | X16: 103.39322 | Z16: 0.1 | AA16: 7.4 | AB16: 248.06394 | AC16: 10701.793 | AD16: 22689.158 | AE16: 4.6458191e+10 | AF16: 6.1801613 | AG16: 7.1348888 | AH16: 0.24616047 | AI16: 46.389627 | AJ16: 95.961365 | AK16: 71.179876 | AL16: 24.590187 | AN16: 65.138803 | AO16: 3.4233933 | AP16: 139.636 | AQ16: 0.5699592 | AR16: 98.43474 | AS16: 138.4 | AV16: 18975 | AW16: 2.7117021e+09 | AX16: 1.9513298e+09 | AZ16: 30470.522 | BA16: -3457446.8 | BB16: 3.625741
A17: 15 | B17: 2022 | C17: YR2022 | D17: Bangladesh | E17: BGD | F17: 169384897 | G17: 1.0242338 | H17: 147570 | I17: 18.7 | J17: 4.8337079e+11 | K17: 2850 | L17: 1.4881024e+12 | M17: 8790 | N17: 8.8 | O17: 74.265 | P17: 2.179 | Q17: 73.128 | R17: 64 | T17: 30.7 | U17: 21.7 | V17: 96 | W17: 96.616371 | X17: 67.038459 | Z17: 0.1 | AA17: 18834 | AB17: 8.5204775 | AC17: 297.11836 | AD17: 602.67475 | AE17: 4.6013169e+11 | AF17: 7.0998288 | AG17: 5.0490219 | AH17: 11.217601 | AI17: 33.92008 | AJ17: 12.882226 | AK17: 20.897741 | AL17: 32.047276 | AN17: 25.042885 | AO17: 0.99098339 | AP17: 109.867 | AR17: 30.347616 | AS17: 73.9 | AT17: 96944431751 | AU17: 1.4213358 | AV17: -549990 | AW17: 1.3524049e+08 | AX17: 1.634888e+09 | AY17: 30.727604 | AZ17: 2716.4859 | BA17: -1.6032899e+09 | BB17: 7.6969544
A18: 16 | B18: 2022 | C18: YR2022 | D18: Barbados | E18: BRB | F18: 282318 | G18: 0.060588347 | H18: 430 | J18: 6.8599939e+09 | K18: 24300 | L18: 6.1144865e+09 | M18: 21660 | O18: 75.676 | P18: 1.712 | Q18: 45.848 | T18: 10.4 | V18: 85 | W18: 87.064383 | X18: 104.22233 | Z18: 1.1 | AA18: 63 | AB18: 82.569745 | AE18: 6884900000 | AF18: 17.226463 | AG18: -1.2507344 | AH18: 1.4488228 | AI18: 12.813548 | AP18: 114.581 | AQ18: 17.011739 | AR18: 38.475504 | AS18: 92.6 | AV18: -80 | AX18: 200000000 | AZ18: 24387.039
A19: 17 | B19: 2022 | C19: YR2022 | D19: Belarus | E19: BLR | F19: 9228071 | G19: -0.80422843 | H19: 207630 | I19: 3.9 | J19: 6.6525039e+10 | K19: 7210 | L19: 2.5133658e+11 | M19: 27240 | O19: 74.103366 | P19: 1.326 | Q19: 9.903 | T19: 2.6 | V19: 98 | W19: 94.224472 | X19: 99.060203 | AA19: 87966 | AB19: 40.505744 | AC19: 2862.487 | AD19: 3902.7658 | AE19: 7.377518e+10 | AF19: -4.6583959 | AG19: 14.884862 | AH19: 8.0418187 | AI19: 33.029096 | AJ19: 63.051187 | AK19: 56.973021 | AL19: 21.597906 | AM19: 26.072572 | AN19: 3.3840785 | AO19: 1.6486931 | AP19: 128.315 | AR19: 103.73543 | AS19: 105.9 | AT19: 3.9858867e+10 | AU19: 9.6340361 | AV19: -8000 | AW19: 1.6465787e+08 | AX19: 1.6064177e+09 | AY19: 1.9016403 | AZ19: 7994.6481 | BA19: -1.4262189e+09 | BB19: 15.209675
A20: 18 | B20: 2022 | C20: YR2022 | D20: Belgium | E20: BEL | F20: 11680210 | G20: 0.80816535 | H20: 30689 | I20: 12.3 | J20: 6.3461778e+11 | K20: 54330 | L20: 8.0538037e+11 | M20: 68950 | N20: 9.4 | O20: 81.74878 | P20: 1.53 | Q20: 4.372 | T20: 3.7 | V20: 96 | X20: 142.91808 | Z20: 0.2 | AA20: 6893 | AB20: 120.84015 | AC20: 4368.4456 | AD20: 7282.7458 | AE20: 5.9108578e+11 | AF20: 3.956238 | AG20: 6.6990376 | AH20: 0.67143041 | AI20: 20.002116 | AJ20: 94.421345 | AK20: 96.757687 | AL20: 27.286481 | AM20: 37.284947 | AO20: 1.1624655 | AP20: 101.68 | AQ20: 22.817914 | AR20: 209.82775 | AS20: 97.1 | AV20: 118615 | AW20: 8.0094049e+09 | AX20: 1.3136474e+10 | AZ20: 50605.75 | BA20: 2.1118314e+10 | BB20: 9.5975117
A21: 19 | B21: 2022 | C21: YR2022 | D21: Belize | E21: BLZ | F21: 402733 | G21: 1.8512481 | H21: 22970 | J21: 2.7020363e+09 | K21: 6710 | L21: 5.1662031e+09 | M21: 12830 | O21: 72.19 | P21: 1.949 | Q21: 53.404 | T21: 12.8 | V21: 81 | W21: 108.6841 | X21: 87.438167 | Z21: 1.2 | AA21: 12547.3 | AB21: 24.971682 | AE21: 2846604350 | AF21: 9.2505133 | AG21: 7.2868549 | AH21: 7.7485812 | AI21: 15.486834 | AJ21: 52.578787 | AK21: 55.261463 | AL21: 20.191917 | AO21: 0.97917379 | AP21: 67.175 | AQ21: 0.00018155445 | AR21: 66.711062 | AS21: 82.5 | AT21: 1.4711929e+09 | AU21: 2.8338486 | AV21: 5936 | AW21: 41395472 | AX21: 1.4090797e+08 | AY21: 52.175796 | AZ21: 7068.2173 | BA21: -1.3970756e+08 | BB21: 6.2768932
A22: 20 | B22: 2022 | C22: YR2022 | D22: Benin | E22: BEN | F22: 13759501 | G22: 2.5474093 | H22: 114760 | J22: 1.8679223e+10 | K22: 1360 | L22: 5.2513064e+10 | M22: 3820 | O22: 60.475 | P22: 4.634 | Q22: 78.86 | R22: 22.4 | T22: 80.4 | V22: 52 | W22: 61.64175 | X22: 43.56065 | Z22: 0.7 | AA22: 30351.5 | AB22: 128.96851 | AC22: 375.82098 | AD22: 105.30905 | AE22: 1.7425405e+10 | AF22: 6.2529471 | AG22: 4.1389945 | AH22: 26.896679 | AI22: 17.017827 | AJ22: 20.81533 | AK22: 23.566263 | AL22: 31.148372 | AO22: 0.63208749 | AP22: 105.745 | AQ22: 4.2871562 | AR22: 49.542607 | AS22: 113 | AT22: 1.092733e+10 | AU22: 2.9869892 | AV22: -192 | AW22: 1.0273129e+08 | AX22: 3.759889e+08 | AY22: 61.663056 | AZ22: 1266.4271 | BA22: -3.294192e+08 | BB22: 1.3507786
A23: 21 | B23: 2022 | C23: YR2022 | D23: Bermuda | E23: BMU | F23: 64749 | G23: 0.15610875 | H23: 4290 | J23: 8.5596245e+09 | K23: 132200 | L23: 7.1740567e+09 | M23: 110800 | O23: 82.062 | P23: 1.397 | Q23: 1.614 | AA23: 10 | AE23: 7874381000 | AF23: 6.4762257 | AG23: 1.4457935 | AH23: 0.21854416 | AI23: 5.3259043 | AJ23: 50.298849 | AK23: 24.898376 | AL23: 12.536566 | AN23: 2.6287781 | AP23: 105.274 | AQ23: 12.540291 | AR23: 15.569478 | AS23: 127.4 | AV23: 0 | AW23: 1.7191032e+08 | AX23: 5893778.6 | AZ23: 121613.94 | BA23: 14707318
A24: 22 | B24: 2022 | C24: YR2022 | D24: Bhutan | E24: BTN | F24: 780914 | G24: 0.70318392 | H24: 38390 | I24: 12.4 | J24: 2.8107952e+09 | K24: 3600 | L24: 1.1152433e+10 | M24: 14280 | N24: 8.8 | O24: 72.754 | P24: 1.478 | Q24: 9.388 | T24: 23.9 | V24: 97 | X24: 89.982913 | Z24: 0.2 | AA24: 27290 | AB24: 7.7415018 | AE24: 2.8982277e+09 | AF24: 5.2138678 | AG24: 5.7948552 | AH24: 14.671012 | AI24: 31.824845 | AJ24: 25.49884 | AK24: 60.072377 | AL24: 55.778829 | AP24: 95.1298 | AQ24: 0.012217994 | AR24: 77.116093 | AS24: 175.1 | AT24: 3.1602431e+09 | AU24: 4.8076292 | AV24: 291 | AW24: 33684108 | AX24: 8402097.1 | AY24: 249.96493 | AZ24: 3711.3277 | BA24: -8402097.1 | BB24: 5.6391667
A25: 23 | B25: 2022 | C25: YR2022 | D25: Bolivia | E25: BOL | F25: 12077154 | G25: 1.1642591 | H25: 1098580 | I25: 37.7 | J25: 5.0617292e+10 | K25: 4190 | L25: 1.4494448e+11 | M25: 12000 | N25: 5.1 | O25: 67.434 | P25: 2.584 | Q25: 65.76 | T25: 23.9 | V25: 69 | W25: 96.544111 | X25: 90.372934 | Z25: 0.4 | AA25: 504164.44 | AB25: 103.57855 | AC25: 798.29322 | AD25: 859.30841 | AE25: 5.0959082e+10 | AF25: 3.7474178 | AG25: 2.5910028 | AH25: 8.6602848 | AI25: 32.019272 | AJ25: 27.793992 | AK25: 29.730942 | AL25: 18.040802 | AO25: 0.97325089 | AP25: 101.572 | AQ25: 5.5176975 | AR25: 50.668103 | AS25: 80.9 | AT25: 1.5930335e+10 | AU25: 4.8399269 | AV25: -3008 | AW25: 3.1930643e+08 | AX25: 6236980.1 | AY25: 27.799163 | AZ25: 4219.4611 | BA25: -87031313 | BB25: 1.7463287
A26: 24 | B26: 2022 | C26: YR2022 | D26: Bosnia and Herzegovina | E26: BIH | F26: 3204802 | G26: -1.243638 | H26: 51210 | J26: 2.469315e+10 | K26: 7710 | L26: 6.6788549e+10 | M26: 20840 | O26: 76.777 | P26: 1.481 | Q26: 11.089 | T26: 6.2 | V26: 58 | W26: 100.88081 | X26: 87.037399 | AA26: 21879.1 | AB26: 64.984062 | AC26: 2270.7264 | AD26: 3773.088 | AE26: 2.4534664e+10 | AF26: 4.2268133 | AG26: 11.808838 | AH26: 4.8262493 | AI26: 24.663248 | AJ26: 48.307127 | AK26: 61.898157 | AL26: 27.902668 | AM26: 35.874435 | AO26: 0.75202873 | AP26: 118.944 | AQ26: 5.2247492 | AR26: 102.10044 | AS26: 108.4 | AT26: 1.3439998e+10 | AU26: 4.1156869 | AV26: -485 | AW26: 1.0786753e+08 | AX26: 9.2943999e+08 | AY26: 88.949334 | AZ26: 7655.5942 | BA26: -8.487529e+08 | BB26: 14.020844
A27: 25 | B27: 2022 | C27: YR2022 | D27: Botswana | E27: BWA | F27: 2439892 | G27: 1.5884802 | H27: 581730 | J27: 2.0124231e+10 | K27: 8250 | L27: 4.8822958e+10 | M27: 20010 | O27: 68.749 | P27: 2.785 | Q27: 54.585 | T27: 40.7 | V27: 90 | W27: 101.53218 | Z27: 17.4 | AA27: 150181 | AB27: 81.913897 | AC27: 1165.1497 | AD27: 1522.1985 | AE27: 2.0321151e+10 | AF27: 5.4860171 | AG27: 14.617677 | AH27: 1.5797898 | AI27: 37.45713 | AJ27: 43.543612 | AK27: 42.068096 | AL27: 26.791518 | AM27: 29.457238 | AN27: 152.67334 | AO27: 2.5177829 | AP27: 178.205 | AQ27: 0.50238129 | AR27: 81.058402 | AS27: 77.3 | AT27: 2.0027171e+09 | AU27: 0.86873765 | AV27: -7306 | AW27: 2.1183442e+08 | AX27: 7.0962414e+08 | AY27: 37.196502 | AZ27: 8328.7091 | BA27: -6.9950613e+08 | BB27: 11.665567
A28: 26 | B28: 2022 | C28: YR2022 | D28: Brazil | E28: BRA | F28: 210306415 | G28: 0.36018089 | H28: 8510420 | J28: 1.7743067e+12 | K28: 8440 | L28: 4.0590625e+12 | M28: 19300 | N28: 3.6 | O28: 74.872 | P28: 1.629 | Q28: 42.881 | T28: 14.6 | V28: 81 | X28: 106.03119 | Z28: 0.7 | AA28: 4941960 | AB28: 27.958569 | AC28: 1432.7274 | AD28: 2787.7609 | AE28: 1.9519238e+12 | AF28: 3.0166944 | AG28: 8.570282 | AH28: 5.7674749 | AI28: 22.819457 | AJ28: 19.630765 | AK28: 19.185301 | AL28: 18.08822 | AM28: 26.936513 | AN28: 40.699226 | AO28: 1.0524008 | AP28: 101.245 | AQ28: 9.1113463 | AR28: 32.090443 | AS28: 114.5 | AT28: 5.7925785e+11 | AU28: 6.6345692 | AV28: -253639 | AW28: 2.2383832e+09 | AX28: 7.5501039e+10 | AY28: 2.7503402 | AZ28: 9281.3328 | BA28: -4.2146446e+10 | BB28: 9.2801061
A29: 27 | B29: 2022 | C29: YR2022 | D29: British Virgin Islands | E29: VGB | F29: 38319 | G29: 1.3398687 | H29: 150 | O29: 77.177 | P29: 1.025 | Q29: 14.539 | T29: 13.1 | X29: 72.284027 | AA29: 36.2 | AP29: 92.8913 | AS29: 56.8 | AV29: 550 | AX29: 38118551090
A30: 28 | B30: 2022 | C30: YR2022 | D30: Brunei Darussalam | E30: BRN | F30: 455370 | G30: 0.80455427 | H30: 5770 | J30: 1.410178e+10 | K30: 30970 | L30: 3.6424679e+10 | M30: 79990 | O30: 72.917 | P30: 1.764 | Q30: 8.589 | T30: 9.5 | V30: 97 | W30: 105.50711 | X30: 89.851365 | AA30: 3800 | AB30: 141.30911 | AC30: 9537.0516 | AD30: 11197.488 | AE30: 1.6681536e+10 | AF30: -1.6283315 | AG30: 24.236727 | AH30: 1.0961603 | AI30: 67.925585 | AJ30: 86.389357 | AK30: 60.584609 | AL30: 25.851043 | AO30: 2.61193 | AP30: 116.108 | AQ30: 1.0442596 | AR30: 140.35877 | AS30: 135.4 | AV30: 0 | AX30: -2.9016998e+08 | AZ30: 36632.928 | BA30: 2.9016998e+08 | BB30: 3.6822503
A31: 29 | B31: 2022 | C31: YR2022 | D31: Bulgaria | E31: BGR | F31: 6465097 | G31: -0.65067613 | H31: 111000 | I31: 20.6 | J31: 8.4717136e+10 | K31: 13100 | L31: 2.1901231e+11 | M31: 33880 | N31: 6.2 | O31: 74.160976 | P31: 1.78 | Q31: 39.409 | T31: 6.2 | V31: 91 | W31: 95.713913 | X31: 96.672073 | Z31: 0.1 | AA31: 39190 | AB31: 11.399265 | AC31: 2968.6566 | AD31: 5536.4985 | AE31: 9.0506153e+10 | AF31: 4.0838641 | AG31: 15.918454 | AH31: 3.7113641 | AI31: 25.303721 | AJ31: 69.979475 | AK31: 68.865402 | AL31: 22.687585 | AM31: 36.54038 | AN31: 17.351958 | AO31: 1.587075 | AP31: 116.679 | AQ31: 10.382678 | AR31: 119.20074 | AS31: 97 | AT31: 4.7206483e+10 | AU31: 10.911661 | AV31: 26498 | AW31: 188040000 | AX31: 5060860000 | AZ31: 13999.195 | BA31: -3798280000 | BB31: 15.325259
A32: 30 | B32: 2022 | C32: YR2022 | D32: Burkina Faso | E32: BFA | F32: 22509038 | G32: 2.3090715 | H32: 274200 | J32: 1.8839307e+10 | K32: 840 | L32: 5.5682079e+10 | M32: 2470 | O32: 60.7 | P32: 4.275 | Q32: 88.56 | R32: 33.96274 | T32: 79.9 | V32: 88 | W32: 58.29119 | X32: 33.621287 | Z32: 0.6 | AA32: 61164 | AB32: 20.371128 | AC32: 312.92909 | AD32: 131.19175 | AE32: 1.8622421e+10 | AF32: 1.6267326 | AG32: 4.6425844 | AH32: 20.629761 | AI32: 26.043949 | AJ32: 31.218073 | AK32: 36.302217 | AL32: 18.058505 | AM32: 19.87263 | AO32: 2.9816157 | AP32: 119.463 | AQ32: 1.528999 | AR32: 53.816847 | AS32: 97.3 | AT32: 9.905922e+09 | AU32: 6.1741813 | AV32: -24960 | AW32: 1.8515886e+08 | AX32: 6.6973824e+08 | AY32: 61.858041 | AZ32: 827.33084 | BA32: -6.4620835e+08 | BB32: 14.290235
A33: 31 | B33: 2022 | C33: YR2022 | D33: Burundi | E33: BDI | F33: 13321097 | G33: 2.7058501 | H33: 27830 | J33: 3.8208988e+09 | K33: 290 | L33: 1.4767842e+10 | M33: 1110 | O33: 62.882 | P33: 4.98 | Q33: 54.08 | T33: 50.8 | U33: 27.6 | V33: 89 | Z33: 0.9 | AA33: 2796.4 | AB33: 12.535792 | AE33: 4.0361926e+09 | AF33: 2.3177012 | AG33: 15.049386 | AH33: 34.683721 | AI33: 16.933802 | AO33: 2.5985809 | AP33: 56.26 | AQ33: 1.1179241 | AR33: 36.346135 | AS33: 101.7 | AT33: 9.4693043e+08 | AU33: 0.82360391 | AV33: 1995 | AW33: 16594853 | AX33: 25249489 | AY33: 43.134304 | AZ33: 302.99251 | BA33: -23299308 | BB33: 18.800879
A34: 32 | B34: 2022 | C34: YR2022 | D34: Cabo Verde | E34: CPV | F34: 519741 | G34: 0.59668835 | H34: 4030 | J34: 2.3661059e+09 | K34: 4550 | L34: 4.8661605e+09 | M34: 9360 | O34: 75.907 | P34: 1.533 | Q34: 38.673 | T34: 12.1 | V34: 95 | W34: 99.098558 | X34: 96.431594 | Z34: 0.9 | AA34: 463.2 | AB34: 11.604527 | AE34: 2.2470033e+09 | AF34: 15.843676 | AG34: 6.3431904 | AH34: 4.9540487 | AI34: 11.078924 | AJ34: 38.684254 | AK34: 58.309883 | AL34: 21.879431 | AO34: 0.45608101 | AP34: 113.247 | AQ34: 3.47654 | AR34: 85.580647 | AS34: 90 | AT34: 2.4025745e+09 | AU34: 4.7338498 | AV34: -1253 | AW34: 30236846 | AX34: 1.2201553e+08 | AY34: 161.45941 | AZ34: 4323.3136 | BA34: -1.0342526e+08 | BB34: 7.9309293
A35: 33 | B35: 2022 | C35: YR2022 | D35: Cambodia | E35: KHM | F35: 17201724 | G35: 1.3308881 | H35: 181040 | J35: 3.8995461e+10 | K35: 2270 | L35: 1.1440189e+11 | M35: 6650 | O35: 70.528 | P35: 2.616 | Q35: 47.089 | R35: 61.9 | S35: 98.7 | T35: 23.8 | V35: 83 | W35: 87.257242 | X35: 55.134681 | Z35: 0.6 | AA35: 77569.9 | AB35: 15.841294 | AC35: 501.64414 | AD35: 813.23244 | AE35: 3.9994533e+10 | AF35: 5.1299011 | AG35: 3.4889002 | AH35: 16.544086 | AI35: 40.864963 | AJ35: 72.207061 | AK35: 73.666572 | AL35: 34.594526 | AM35: 14.953851 | AO35: 1.5418835 | AP35: 113.392 | AQ35: 6.562226 | AR35: 130.71036 | AS35: 80.9 | AT35: 2.2473751e+10 | AU35: 7.0957763 | AV35: -31350 | AW35: 3.0233623e+08 | AX35: 3.5788313e+09 | AY35: 90.046382 | AZ35: 2325.0305 | BA35: -3.428345e+09 | BB35: 5.3437026
A36: 34 | B36: 2022 | C36: YR2022 | D36: Cameroon | E36: CMR | F36: 27632771 | G36: 2.6290509 | H36: 475440 | J36: 4.574751e+10 | K36: 1660 | L36: 1.3981233e+11 | M36: 5060 | O36: 62.443 | P36: 4.397 | Q36: 108.328 | T36: 69.5 | V36: 68 | W36: 70.436817 | X36: 45.606672 | Z36: 2.8 | AA36: 202284.8 | AB36: 37.033138 | AC36: 384.10486 | AD36: 283.6849 | AE36: 4.4347206e+10 | AF36: 3.736784 | AG36: 6.8310547 | AH36: 16.546164 | AI36: 27.130359 | AJ36: 19.321813 | AK36: 21.964789 | AL36: 19.10744 | AO36: 0.93935295 | AP36: 89.8274 | AQ36: 3.2886471 | AR36: 30.346895 | AS36: 124.4 | AT36: 1.5122663e+10 | AU36: 4.1884174 | AV36: -4798 | AW36: 32278963 | AX36: 9.2568155e+08 | AY36: 42.957077 | AZ36: 1604.8773 | BA36: -8.9833537e+08 | BB36: 6.2476771
A37: 35 | B37: 2022 | C37: YR2022 | D37: Canada | E37: CAN | F37: 38935934 | G37: 1.8039046 | H37: 15634410 | J37: 2.0967552e+12 | K37: 53850 | L37: 2.4406215e+12 | M37: 62680 | O37: 81.245366 | P37: 1.33 | Q37: 4.889 | T37: 5.1 | V37: 92 | X37: 107.47938 | Z37: 0.1 | AA37: 3468541.3 | AB37: 49.22784 | AC37: 7578.0209 | AD37: 14907.078 | AE37: 2.1904111e+12 | AF37: 4.1890363 | AG37: 7.9067621 | AJ37: 33.943191 | AK37: 33.374431 | AL37: 25.318667 | AM37: 18.972304 | AN37: 126.04353 | AO37: 1.1671326 | AP37: 91.2387 | AQ37: 15.148977 | AR37: 54.254291 | AS37: 121.1 | AV37: 459988 | AW37: 1.0423274e+10 | AX37: 5.0229921e+10 | AZ37: 56256.801 | BA37: 3.8444704e+10 | BB37: 6.8028012
A38: 36 | B38: 2022 | C38: YR2022 | D38: Cayman Islands | E38: CYM | F38: 71591 | G38: 2.0932458 | H38: 264 | J38: 5.3017233e+09 | K38: 74060 | L38: 4.6334141e+09 | M38: 64720 | O38: 79.984 | P38: 1.541 | Q38: 11.515 | W38: 97.956577 | X38: 85.601227 | AA38: 126.4 | AE38: 6.6601612e+09 | AF38: 5.7756671 | AG38: 3.8886317 | AH38: 0.4689399 | AI38: 8.0805517 | AP38: 139.315 | AQ38: 56.646705 | AR38: 27.536871 | AS38: 143.2 | AV38: 942 | AW38: 5.3882516e+08 | AX38: -3.1447364e+09 | AZ38: 93030.705 | BA38: 2.377418e+09
A39: 37 | B39: 2022 | C39: YR2022 | D39: Central African Republic | E39: CAF | F39: 5098039 | G39: -0.27543227 | H39: 622980 | J39: 2.6656252e+09 | K39: 520 | L39: 6.538857e+09 | M39: 1280 | O39: 18.818 | P39: 6.023 | Q39: 163.019 | T39: 387.4 | U39: 18.4 | V39: 32 | Z39: 2.7 | AA39: 222430 | AB39: 28.050845 | AE39: 2.3826186e+09 | AF39: 0.45390188 | AG39: 6.0187788 | AH39: 36.21711 | AI39: 21.1573 | AJ39: 12.3005 | AK39: 32.93307 | AL39: 24.32666 | AO39: 1.7108622 | AP39: 38.8218 | AQ39: 37.297405 | AR39: 24.636759 | AS39: 96.5 | AT39: 1.0455113e+09 | AU39: 0.79256819 | AV39: -17430 | AX39: 24047720 | AY39: 134.13358 | AZ39: 467.35983 | BB39: 5.5831674
A40: 38 | B40: 2022 | C40: YR2022 | D40: Chad | E40: TCD | F40: 18455316 | G40: 3.4566891 | H40: 1284000 | I40: 44.8 | J40: 1.7553237e+10 | K40: 950 | L40: 4.7929337e+10 | M40: 2600 | N40: 6.9 | O40: 54.528 | P40: 6.215 | Q40: 136.697 | T40: 104.3 | U40: 18.2 | V40: 54 | Z40: 1 | AA40: 40914.444 | AB40: 18.098675 | AC40: 198.54477 | AD40: 14.467376 | AE40: 1.7828508e+10 | AF40: 4.129699 | AG40: 14.147701 | AH40: 35.227982 | AI40: 33.063605 | AJ40: 31.735344 | AK40: 16.253034 | AL40: 17.971522 | AO40: 2.0442448 | AP40: 65.4378 | AR40: 34.377526 | AS40: 158.6 | AT40: 3.2696582e+09 | AU40: 2.3891098 | AV40: 36670 | AX40: 614018510 | AY40: 38.055124 | AZ40: 966.03647 | BB40: 5.7880269
...

Sheet regions
A1: name | B1: alpha-2 | C1: alpha-3 | D1: country-code | E1: iso_3166-2 | F1: region | G1: sub-region | H1: intermediate-region | I1: region-code | J1: sub-region-code | K1: intermediate-region-code
A2: Afghanistan | B2: AF | C2: AFG | D2: 4 | E2: ISO 3166-2:AF | F2: Asia | G2: Southern Asia | I2: 142 | J2: 34
A3: Åland Islands | B3: AX | C3: ALA | D3: 248 | E3: ISO 3166-2:AX | F3: Europe | G3: Northern Europe | I3: 150 | J3: 154
A4: Albania | B4: AL | C4: ALB | D4: 8 | E4: ISO 3166-2:AL | F4: Europe | G4: Southern Europe | I4: 150 | J4: 39
A5: Algeria | B5: DZ | C5: DZA | D5: 12 | E5: ISO 3166-2:DZ | F5: Africa | G5: Northern Africa | I5: 2 | J5: 15
A6: American Samoa | B6: AS | C6: ASM | D6: 16 | E6: ISO 3166-2:AS | F6: Oceania | G6: Polynesia | I6: 9 | J6: 61
A7: Andorra | B7: AD | C7: AND | D7: 20 | E7: ISO 3166-2:AD | F7: Europe | G7: Southern Europe | I7: 150 | J7: 39
A8: Angola | B8: AO | C8: AGO | D8: 24 | E8: ISO 3166-2:AO | F8: Africa | G8: Sub-Saharan Africa | H8: Middle Africa | I8: 2 | J8: 202 | K8: 17
A9: Anguilla | B9: AI | C9: AIA | D9: 660 | E9: ISO 3166-2:AI | F9: Americas | G9: Latin America and the Caribbean | H9: Caribbean | I9: 19 | J9: 419 | K9: 29
A10: Antarctica | B10: AQ | C10: ATA | D10: 10 | E10: ISO 3166-2:AQ
A11: Antigua and Barbuda | B11: AG | C11: ATG | D11: 28 | E11: ISO 3166-2:AG | F11: Americas | G11: Latin America and the Caribbean | H11: Caribbean | I11: 19 | J11: 419 | K11: 29
A12: Argentina | B12: AR | C12: ARG | D12: 32 | E12: ISO 3166-2:AR | F12: Americas | G12: Latin America and the Caribbean | H12: South America | I12: 19 | J12: 419 | K12: 5
A13: Armenia | B13: AM | C13: ARM | D13: 51 | E13: ISO 3166-2:AM | F13: Asia | G13: Western Asia | I13: 142 | J13: 145
A14: Aruba | B14: AW | C14: ABW | D14: 533 | E14: ISO 3166-2:AW | F14: Americas | G14: Latin America and the Caribbean | H14: Caribbean | I14: 19 | J14: 419 | K14: 29
A15: Australia | B15: AU | C15: AUS | D15: 36 | E15: ISO 3166-2:AU | F15: Oceania | G15: Australia and New Zealand | I15: 9 | J15: 53
A16: Austria | B16: AT | C16: AUT | D16: 40 | E16: ISO 3166-2:AT | F16: Europe | G16: Western Europe | I16: 150 | J16: 155
A17: Azerbaijan | B17: AZ | C17: AZE | D17: 31 | E17: ISO 3166-2:AZ | F17: Asia | G17: Western Asia | I17: 142 | J17: 145
A18: Bahamas | B18: BS | C18: BHS | D18: 44 | E18: ISO 3166-2:BS | F18: Americas | G18: Latin America and the Caribbean | H18: Caribbean | I18: 19 | J18: 419 | K18: 29
A19: Bahrain | B19: BH | C19: BHR | D19: 48 | E19: ISO 3166-2:BH | F19: Asia | G19: Western Asia | I19: 142 | J19: 145
A20: Bangladesh | B20: BD | C20: BGD | D20: 50 | E20: ISO 3166-2:BD | F20: Asia | G20: Southern Asia | I20: 142 | J20: 34
A21: Barbados | B21: BB | C21: BRB | D21: 52 | E21: ISO 3166-2:BB | F21: Americas | G21: Latin America and the Caribbean | H21: Caribbean | I21: 19 | J21: 419 | K21: 29
A22: Belarus | B22: BY | C22: BLR | D22: 112 | E22: ISO 3166-2:BY | F22: Europe | G22: Eastern Europe | I22: 150 | J22: 151
A23: Belgium | B23: BE | C23: BEL | D23: 56 | E23: ISO 3166-2:BE | F23: Europe | G23: Western Europe | I23: 150 | J23: 155
A24: Belize | B24: BZ | C24: BLZ | D24: 84 | E24: ISO 3166-2:BZ | F24: Americas | G24: Latin America and the Caribbean | H24: Central America | I24: 19 | J24: 419 | K24: 13
A25: Benin | B25: BJ | C25: BEN | D25: 204 | E25: ISO 3166-2:BJ | F25: Africa | G25: Sub-Saharan Africa | H25: Western Africa | I25: 2 | J25: 202 | K25: 11
A26: Bermuda | B26: BM | C26: BMU | D26: 60 | E26: ISO 3166-2:BM | F26: Americas | G26: Northern America | I26: 19 | J26: 21
A27: Bhutan | B27: BT | C27: BTN | D27: 64 | E27: ISO 3166-2:BT | F27: Asia | G27: Southern Asia | I27: 142 | J27: 34
A28: Bolivia, Plurinational State of | B28: BO | C28: BOL | D28: 68 | E28: ISO 3166-2:BO | F28: Americas | G28: Latin America and the Caribbean | H28: South America | I28: 19 | J28: 419 | K28: 5
A29: Bonaire, Sint Eustatius and Saba | B29: BQ | C29: BES | D29: 535 | E29: ISO 3166-2:BQ | F29: Americas | G29: Latin America and the Caribbean | H29: Caribbean | I29: 19 | J29: 419 | K29: 29
A30: Bosnia and Herzegovina | B30: BA | C30: BIH | D30: 70 | E30: ISO 3166-2:BA | F30: Europe | G30: Southern Europe | I30: 150 | J30: 39
A31: Botswana | B31: BW | C31: BWA | D31: 72 | E31: ISO 3166-2:BW | F31: Africa | G31: Sub-Saharan Africa | H31: Southern Africa | I31: 2 | J31: 202 | K31: 18
A32: Bouvet Island | B32: BV | C32: BVT | D32: 74 | E32: ISO 3166-2:BV | F32: Americas | G32: Latin America and the Caribbean | H32: South America | I32: 19 | J32: 419 | K32: 5
A33: Brazil | B33: BR | C33: BRA | D33: 76 | E33: ISO 3166-2:BR | F33: Americas | G33: Latin America and the Caribbean | H33: South America | I33: 19 | J33: 419 | K33: 5
A34: British Indian Ocean Territory | B34: IO | C34: IOT | D34: 86 | E34: ISO 3166-2:IO | F34: Africa | G34: Sub-Saharan Africa | H34: Eastern Africa | I34: 2 | J34: 202 | K34: 14
A35: Brunei Darussalam | B35: BN | C35: BRN | D35: 96 | E35: ISO 3166-2:BN | F35: Asia | G35: South-eastern Asia | I35: 142 | J35: 35
A36: Bulgaria | B36: BG | C36: BGR | D36: 100 | E36: ISO 3166-2:BG | F36: Europe | G36: Eastern Europe | I36: 150 | J36: 151
A37: Burkina Faso | B37: BF | C37: BFA | D37: 854 | E37: ISO 3166-2:BF | F37: Africa | G37: Sub-Saharan Africa | H37: Western Africa | I37: 2 | J37: 202 | K37: 11
A38: Burundi | B38: BI | C38: BDI | D38: 108 | E38: ISO 3166-2:BI | F38: Africa | G38: Sub-Saharan Africa | H38: Eastern Africa | I38: 2 | J38: 202 | K38: 14
A39: Cabo Verde | B39: CV | C39: CPV | D39: 132 | E39: ISO 3166-2:CV | F39: Africa | G39: Sub-Saharan Africa | H39: Western Africa | I39: 2 | J39: 202 | K39: 11
A40: Cambodia | B40: KH | C40: KHM | D40: 116 | E40: ISO 3166-2:KH | F40: Asia | G40: South-eastern Asia | I40: 142 | J40: 35
...

Sheet matches
A1: Column1 | B1: original | C1: matched
A2: 0 | B2: Afghanistan | C2: Afghanistan
A3: 1 | B3: Albania | C3: Albania
A4: 2 | B4: Algeria | C4: Algeria
A5: 3 | B5: American Samoa | C5: American Samoa
A6: 4 | B6: Andorra | C6: Andorra
A7: 5 | B7: Angola | C7: Angola
A8: 6 | B8: Antigua and Barbuda | C8: Antigua and Barbuda
A9: 7 | B9: Argentina | C9: Argentina
A10: 8 | B10: Armenia | C10: Armenia
A11: 9 | B11: Aruba | C11: Aruba
A12: 10 | B12: Australia | C12: Australia
A13: 11 | B13: Austria | C13: Austria
... A218: 216 | B218: Zimbabwe | C218: Zimbabwe

Sheet Sheet1
A1: Country name | B1: Match | C1: Region | D1: Population, total [SP.POP.TOTL] | E1: Surface area (sq. km) [AG.SRF.TOTL.K2] | F1: Life expectancy at birth, total (years) [SP.DYN.LE00.IN] | G1: GDP (current US$) [NY.GDP.MKTP.CD] | H1: Mobile cellular subscriptions (per 100 people) [IT.CEL.SETS.P2] | I1: GDP per capita (current US$) [NY.GDP.PCAP.CD]
A2: Afghanistan | B2: Afghanistan | C2: =_xlfn.XLOOKUP(B2,'regions'!A:A,'regions'!F:F) -> Asia | D2: 40578842 | E2: 652860 | F2: 65.617 | G2: 1.4497244e+10 | H2: 56.2655 | I2: 357.26115
A3: Albania | B3: Albania | C3: =_xlfn.XLOOKUP(B3,'regions'!A:A,'regions'!F:F) -> Europe | D3: 2451636 | E3: 28750 | F3: 78.769 | G3: 1.9017247e+10 | H3: 98.395 | I3: 7756.9619
A4: Algeria | B4: Algeria | C4: =_xlfn.XLOOKUP(B4,'regions'!A:A,'regions'!F:F) -> Africa | D4: 45477389 | E4: 2381740 | F4: 76.129 | G4: 2.2558164e+11 | H4: 107.787 | I4: 4960.3033
A5: American Samoa | B5: American Samoa | C5: =_xlfn.XLOOKUP(B5,'regions'!A:A,'regions'!F:F) -> Oceania | D5: 48342 | E5: 200 | F5: 72.752 | G5: 871000000 | I5: 18017.459
A6: Andorra | B6: Andorra | C6: =_xlfn.XLOOKUP(B6,'regions'!A:A,'regions'!F:F) -> Europe | D6: 79705 | E6: 470 | F6: 84.016 | G6: 3.3806117e+09 | H6: 142.426 | I6: 42414.048
A7: Angola | B7: Angola | C7: =_xlfn.XLOOKUP(B7,'regions'!A:A,'regions'!F:F) -> Africa | D7: 35635029 | E7: 1246700 | F7: 64.246 | G7: 1.3121221e+11 | H7: 66.6008 | I7: 3682.1132
A8: Antigua and Barbuda | B8: Antigua and Barbuda | C8: =_xlfn.XLOOKUP(B8,'regions'!A:A,'regions'!F:F) -> Americas | D8: 92840 | E8: 440 | F8: 77.483 | G8: 1.8665667e+09 | H8: 200.541 | I8: 20105.199
A9: Argentina | B9: Argentina | C9: =_xlfn.XLOOKUP(B9,'regions'!A:A,'regions'!F:F) -> Americas | D9: 45407904 | E9: 2780400 | F9: 75.806 | G9: 6.3399376e+11 | H9: 131.484 | I9: 13962.189
A10: Armenia | B10: Armenia | C10: =_xlfn.XLOOKUP(B10,'regions'!A:A,'regions'!F:F) -> Asia | D10: 2969200 | E10: 29740 | F10: 74.765854 | G10: 1.9513507e+10 | H10: 130.54 | I10: 6571.9745
A11: Aruba | B11: Aruba | C11: =_xlfn.XLOOKUP(B11,'regions'!A:A,'regions'!F:F) -> Americas | D11: 107310 | E11: 180 | F11: 76.226 | G11: 3.3240344e+09 | H11: 130.648 | I11: 30975.999
A12: Australia | B12: Australia | C12: =_xlfn.XLOOKUP(B12,'regions'!A:A,'regions'!F:F) -> Oceania | D12: 26018721 | E12: 7741220 | F12: 83.2 | G12: 1.6956275e+12 | H12: 109.469 | I12: 65169.519
A13: Austria | B13: Austria | C13: =_xlfn.XLOOKUP(B13,'regions'!A:A,'regions'!F:F) -> Europe | D13: 9041851 | E13: 83879 | F13: 81.295122 | G13: 4.732213e+11 | H13: 121.166 | I13: 52336.773
A14: Azerbaijan | B14: Azerbaijan | C14: =_xlfn.XLOOKUP(B14,'regions'!A:A,'regions'!F:F) -> Asia | D14: 10141756 | E14: 86600 | F14: 74.125 | G14: 7.8807471e+10 | H14: 107.506 | I14: 7770.5942
A15: Bahamas, The | B15: Bahamas | C15: =_xlfn.XLOOKUP(B15,'regions'!A:A,'regions'!F:F) -> Americas | D15: 397538 | E15: 13880 | F15: 74.491 | G15: 13896800000 | H15: 101.624 | I15: 34957.161
A16: Bahrain | B16: Bahrain | C16: =_xlfn.XLOOKUP(B16,'regions'!A:A,'regions'!F:F) -> Asia | D16: 1524693 | E16: 790 | F16: 80.992 | G16: 4.6458191e+10 | H16: 139.636 | I16: 30470.522
A17: Bangladesh | B17: Bangladesh | C17: =_xlfn.XLOOKUP(B17,'regions'!A:A,'regions'!F:F) -> Asia | D17: 169384897 | E17: 147570 | F17: 74.265 | G17: 4.6013169e+11 | H17: 109.867 | I17: 2716.4859
... A28: Brazil | B28: Brazil | C28: =_xlfn.XLOOKUP(B28,'regions'!A:A,'regions'!F:F) -> Americas | D28: 210306415 | E28: 8510420 | F28: 74.872 | G28: 1.9519238e+12 | H28: 101.245 | I28: 9281.3328
A29: British Virgin Islands | B29: Virgin Islands (British) | C29: =_xlfn.XLOOKUP(B29,'regions'!A:A,'regions'!F:F) -> Americas | D29: 38319 | E29: 150 | F29: 77.177 | H29: 92.8913
A30: Brunei Darussalam | B30: Brunei Darussalam | C30: =_xlfn.XLOOKUP(B30,'regions'!A:A,'regions'!F:F) -> Asia | D30: 455370 | E30: 5770 | F30: 72.917 | G30: 1.6681536e+10 | H30: 116.108 | I30: 36632.928
A31: Bulgaria | B31: Bulgaria | C31: =_xlfn.XLOOKUP(B31,'regions'!A:A,'regions'!F:F) -> Europe | D31: 6465097 | E31: 111000 | F31: 74.160976 | G31: 9.0506153e+10 | H31: 116.679 | I31: 13999.195
A32: Burkina Faso | B32: Burkina Faso | C32: =_xlfn.XLOOKUP(B32,'regions'!A:A,'regions'!F:F) -> Africa | D32: 22509038 | E32: 274200 | F32: 60.7 | G32: 1.8622421e+10 | H32: 119.463 | I32: 827.33084
A33: Burundi | B33: Burundi | C33: =_xlfn.XLOOKUP(B33,'regions'!A:A,'regions'!F:F) -> Africa | D33: 13321097 | E33: 27830 | F33: 62.882 | G33: 4.0361926e+09 | H33: 56.26 | I33: 302.99251
A34: Cabo Verde | B34: Cabo Verde | C34: =_xlfn.XLOOKUP(B34,'regions'!A:A,'regions'!F:F) -> Africa | D34: 519741 | E34: 4030 | F34: 75.907 | G34: 2.2470033e+09 | H34: 113.247 | I34: 4323.3136
A35: Cambodia | B35: Cambodia | C35: =_xlfn.XLOOKUP(B35,'regions'!A:A,'regions'!F:F) -> Asia | D35: 17201724 | E35: 181040 | F35: 70.528 | G35: 3.9994533e+10 | H35: 113.392 | I35: 2325.0305
A36: Cameroon | B36: Cameroon | C36: =_xlfn.XLOOKUP(B36,'regions'!A:A,'regions'!F:F) -> Africa | D36: 27632771 | E36: 475440 | F36: 62.443 | G36: 4.4347206e+10 | H36: 89.8274 | I36: 1604.8773
A37: Canada | B37: Canada | C37: =_xlfn.XLOOKUP(B37,'regions'!A:A,'regions'!F:F) -> Americas | D37: 38935934 | E37: 15634410 | F37: 81.245366 | G37: 2.1904111e+12 | H37: 91.2387 | I37: 56256.801
A38: Cayman Islands | B38: Cayman Islands | C38: =_xlfn.XLOOKUP(B38,'regions'!A:A,'regions'!F:F) -> Americas | D38: 71591 | E38: 264 | F38: 79.984 | G38: 6.6601612e+09 | H38: 139.315 | I38: 93030.705
A39: Central African Republic | B39: Central African Republic | C39: =_xlfn.XLOOKUP(B39,'regions'!A:A,'regions'!F:F) -> Africa | D39: 5098039 | E39: 622980 | F39: 18.818 | G39: 2.3826186e+09 | H39: 38.8218 | I39: 467.35983
A40: Chad | B40: Chad | C40: =_xlfn.XLOOKUP(B40,'regions'!A:A,'regions'!F:F) -> Africa | D40: 18455316 | E40: 1284000 | F40: 54.528 | G40: 1.7828508e+10 | H40: 65.4378 | I40: 966.03647
A41: Channel Islands | B41: Cocos (Keeling) Islands | C41: =_xlfn.XLOOKUP(B41,'regions'!A:A,'regions'!F:F) -> Oceania | D41: 167215 | F41: 81 | G41: 1.1308273e+10 | I41: 67627.142
A42: Chile | B42: Chile | C42: =_xlfn.XLOOKUP(B42,'regions'!A:A,'regions'!F:F) -> Americas | D42: 19553036 | E42: 757244.88 | F42: 79.176 | G42: 3.0122658e+11 | H42: 135.114 | I42: 15405.617
A43: China | B43: China | C43: =_xlfn.XLOOKUP(B43,'regions'!A:A,'regions'!F:F) -> Asia | D43: 1412175000 | E43: 9562910 | F43: 78.202 | G43: 1.8316765e+13 | H43: 124.195 | I43: 12970.606
A44: Colombia | B44: Colombia | C44: =_xlfn.XLOOKUP(B44,'regions'!A:A,'regions'!F:F) -> Americas | D44: 51737944 | E44: 1140619.1 | F44: 76.508 | G44: 3.4563249e+11 | H44: 156.195 | I44: 6680.4451
A45: Comoros | B45: Comoros | C45: =_xlfn.XLOOKUP(B45,'regions'!A:A,'regions'!F:F) -> Africa | D45: 834188 | E45: 1861 | F45: 66.481 | G45: 1.2224855e+09 | H45: 100.549 | I45: 1465.4796
A46: Congo, Dem. Rep. | B46: Congo | C46: =_xlfn.XLOOKUP(B46,'regions'!A:A,'regions'!F:F) -> Africa | D46: 102396968 | E46: 2344860 | F46: 60.979 | G46: 7.0422346e+10 | H46: 48.6774 | I46: 687.73859
A47: Congo, Rep. | B47: Congo | C47: =_xlfn.XLOOKUP(B47,'regions'!A:A,'regions'!F:F) -> Africa | D47: 6035104 | E47: 342000 | F47: 65 | G47: 1.581703e+10 | H47: 93.6259 | I47: 2620.838
A48: Costa Rica | B48: Costa Rica | C48: =_xlfn.XLOOKUP(B48,'regions'!A:A,'regions'!F:F) -> Americas | D48: 5081765 | E48: 51100 | F48: 79.316 | G48: 6.9243626e+10 | H48: 154.989 | I48: 13625.901
A49: Cote d'Ivoire | B49: Côte d'Ivoire | C49: =_xlfn.XLOOKUP(B49,'regions'!A:A,'regions'!F:F) -> Africa | D49: 30395002 | E49: 322460 | F49: 61.562 | G49: 7.0922825e+10 | H49: 161.232 | I49: 2333.3713
A50: Croatia | B50: Croatia | C50: =_xlfn.XLOOKUP(B50,'regions'!A:A,'regions'!F:F) -> Europe | D50: 3855641 | E50: 88070 | F50: 77.57561 | G50: 7.1196499e+10 | H50: 114.677 | I50: 18465.541
...
